On branch main
Your branch is up to date with 'origin/main'.

nothing to commit, working tree clean
Everything up-to-date
[main 12f4d7a] DJOTD 2022-11-15
 1 file changed, 5 insertions(+)
To https://github.com/FluffyCube9343/FluffyCube9343.git
   ea16caa..12f4d7a  main -> main
started!
initialized!
[main 5807834] DJOTD 2022-11-16
 2 files changed, 69 insertions(+), 1 deletion(-)
Traceback (most recent call last):
  File "/home/ubuntu/FluffyCube9343/main.py", line 30, in <module>
    else:
FileNotFoundError: [Errno 2] No such file or directory: 'README.md'
To https://github.com/FluffyCube9343/FluffyCube9343.git
   7c29597..5807834  main -> main
[main e85e0b6] DJOTD 2022-11-17
 2 files changed, 9 insertions(+), 1 deletion(-)
To https://github.com/FluffyCube9343/FluffyCube9343.git
 ! [rejected]        main -> main (fetch first)
error: failed to push some refs to 'https://github.com/FluffyCube9343/FluffyCube9343.git'
hint: Updates were rejected because the remote contains work that you do
hint: not have locally. This is usually caused by another repository pushing
hint: to the same ref. You may want to first integrate the remote changes
hint: (e.g., 'git pull ...') before pushing again.
hint: See the 'Note about fast-forwards' in 'git push --help' for details.
